Workbook

Sheet Dashboard
C2: Total Collection (Construction) | E2: =Donation!G749 -> 2495038
C3: Expenses | E3: =J13 -> 2391826
C4: Feb | E4: ='Monthly Sheet'!F3 -> 12500
C5: March | E5: ='Monthly Sheet'!K3 -> 8500
C6: April | E6: ='Monthly Sheet'!P3 -> 8500
C7: May | E7: ='Monthly Sheet'!U3 -> 3000
C8: June | E8: ='Monthly Sheet'!Z3 -> 4500
C9: July | E9: ='Monthly Sheet'!AE3 -> 2000
C13: Total In Hand | E13: =Sum(E2,E4,E5,E6,E7,E8, E9,E10,E11)-E3 -> 142212

Sheet Detail1
A1: Voucher Number | B1: Date | C1: Particular | D1: Category | E1: Bill Date | F1: Amount
A2: 1 | B2: 45804 | C2: Contractor Harmeet | D2: Construction | E2: 45958 | F2: 30000
A3: 2 | B3: 45806 | C3: God Idol:Shivling,Nandiji,Jaleri | D3: Idols | E3: 45806 | F3: 31000
A4: 3 | B4: 45806 | C4: Labour food(Harmeet) | D4: Construction | E4: 45958 | F4: 220
A5: 4 | B5: 45807 | C5: Security Guard on sthapana | D5: Event | E5: 45807 | F5: 200
A6: 5 | B6: 45807 | C6: Panditji Dakshina for sthapana | D6: Event | E6: 45807 | F6: 3200
A7: 6 | B7: 45807 | C7: Pooja Ka Saman for sthapana | D7: Event | E7: 45807 | F7: 1000
A8: 7 | B8: 45807 | C8: Labour(Harmeet) for sthapana | D8: Construction | E8: 45958 | F8: 1000
A9: 8 | B9: 45807 | C9: Flower Petal for sthpana | D9: Event | E9: 45807 | F9: 500
A10: 9 | B10: 45807 | C10: Fruit for sthapana & Prasad | D10: Event | E10: 45807 | F10: 1200
A11: 10 | B11: 45807 | C11: God Idol:Nag Devta,Ghanti,Jhanda | D11: Idols | E11: 45807 | F11: 7000
A12: 11 | B12: 45807 | C12: Water Bottles on Sthapana | D12: Event | E12: 45807 | F12: 310
A13: 12 | B13: 45808 | C13: Contractor Harmeet (Payment to Kushal Garg (1000 Bricks) | D13: Construction | E13: 45958 | F13: 7000
... A45: 41 | B45: 45860 | C45: Dholki wala payment by Amit vats | D45: Event | E45: 45860 | F45: 700
A46: 42 | B46: 45860 | C46: Hanuman Ji Photo Payment by Amit Vats | F46: 1000
A47: 43 | B47: 45860 | C47: Steel Drain Jaali, Stone jointer, Chain/Hook & Cast Iron jali payment to Pranay | D47: Construction | E47: 45860 | F47: 450
A48: 44 | B48: 45860 | C48: Elbow(2) & Socket(2) Payment to Jindal Interiors by Gaurav Ji | D48: Construction | E48: 45860 | F48: 560
A49: 45 | B49: 45860 | C49: Tray(1), Container (3), Platic Tubs(2) to Nanda Ji | F49: 3400
A50: 46 | B50: 45861 | C50: Wiper (2) Payment to Nanda Ji | F50: 500
A51: 47 | B51: 45861 | C51: Flex Printing(2) payment to Nanda ji | F51: 240
A52: 48 | B52: 45860 | C52: Payment to mayank for saman(vijay Sharma) | D52: Event | E52: 45860 | F52: 1000
A53: 49 | B53: 45860 | C53: Sundarkand (10), Chunni (2) payment to Mayank | D53: Event | E53: 45860 | F53: 1740
A54: 50 | B54: 45860 | C54: 2 Folding Bed payment to Mayank | D54: Ops | E54: 45858 | F54: 3600
A55: 51 | B55: 45863 | C55: Stool (12) | D55: Ops | E55: 45863 | F55: 5430
A56: 52 | B56: 45857 | C56: 2 Permanent Marker | D56: Ops | E56: 45857 | F56: 70
A57: 53 | B57: 45857 | C57: Tea Advance | D57: Ops | E57: 45857 | F57: 200
A58: 54 | B58: 45864 | C58: Board & Lock (1 each) | D58: Ops | E58: 45864 | F58: 600
A59: 55 | B59: 45865 | C59: Bathroom Fittings - Store | D59: Construction | E59: 45865 | F59: 375
A60: 56 | B60: 45865 | C60: Electrical material for Store(Extension Board) | D60: Ops | E60: 45865 | F60: 300
A61: 57 | B61: 45865 | C61: Electrical material for Store | D61: Ops | E61: 45865 | F61: 1500
A62: 58 | B62: 45865 | C62: Ansh Phool Wala (26/6/2025 to 31/7/2025) payment done | D62: Ops | E62: No Bill | F62: 2720
A63: 59 | B63: 45865 | C63: Musical Instrument for mandir | F63: 550
A64: 60 | B64: 45865 | C64: Glass Fitting (Flat) + Safai Payment | D64: Ops | E64: 45865 | F64: 800
A65: 61 | B65: 45866 | C65: Dariya (5) | D65: Ops | E65: 45878 | F65: 1500
A66: 62 | B66: 45866 | C66: Recipt Books (6) | D66: Ops | E66: 45866 | F66: 700
A67: 63 | B67: 45867 | C67: Tables (2) | D67: Ops | E67: 45867 | F67: 3200
A68: 64 | B68: 45868 | C68: Payment to Harmeet Contractor | D68: Construction | E68: 45958 | F68: 63650
A69: 65 | B69: 45866 | C69: Bedsheet (3) | D69: Ops | E69: 45866 | F69: 800
A70: 66 | B70: 45871 | C70: Washroom Cleaner + Tea,+ Lassi +Notepad | D70: Ops | E70: 45871 | F70: 330
A71: 67 | B71: 45873 | C71: Garbage Bag | D71: Ops | E71: 45873 | F71: 85
...

Sheet Expense Statement
A1: Voucher Number | B1: Date | C1: Particular | D1: Category | E1: Bill Date | F1: Amount
A2: 1 | B2: 45804 | C2: Contractor Harmeet | D2: Construction | E2: 45958 | F2: 30000
A3: 2 | B3: 45806 | C3: God Idol:Shivling,Nandiji,Jaleri | D3: Idols | E3: 45806 | F3: 31000
A4: 3 | B4: 45806 | C4: Labour food(Harmeet) | D4: Construction | E4: 45958 | F4: 220
A5: 4 | B5: 45807 | C5: Security Guard on sthapana | D5: Event | E5: 45807 | F5: 200
A6: 5 | B6: 45807 | C6: Panditji Dakshina for sthapana | D6: Event | E6: 45807 | F6: 3200
A7: 6 | B7: 45807 | C7: Pooja Ka Saman for sthapana | D7: Event | E7: 45807 | F7: 1000
A8: 7 | B8: 45807 | C8: Labour(Harmeet) for sthapana | D8: Construction | E8: 45958 | F8: 1000
A9: 8 | B9: 45807 | C9: Flower Petal for sthpana | D9: Event | E9: 45807 | F9: 500
A10: 9 | B10: 45807 | C10: Fruit for sthapana & Prasad | D10: Event | E10: 45807 | F10: 1200
A11: 10 | B11: 45807 | C11: God Idol:Nag Devta,Ghanti,Jhanda | D11: Idols | E11: 45807 | F11: 7000
A12: 11 | B12: 45807 | C12: Water Bottles on Sthapana | D12: Event | E12: 45807 | F12: 310
A13: 12 | B13: 45808 | C13: Contractor Harmeet (Payment to Kushal Garg (1000 Bricks) | D13: Construction | E13: 45958 | F13: 7000
... A45: 41 | B45: 45860 | C45: Dholki wala payment by Amit vats | D45: Event | E45: 45860 | F45: 700
A46: 42 | B46: 45860 | C46: Hanuman Ji Photo Payment by Amit Vats | F46: 1000
A47: 43 | B47: 45860 | C47: Steel Drain Jaali, Stone jointer, Chain/Hook & Cast Iron jali payment to Pranay | D47: Construction | E47: 45860 | F47: 450
A48: 44 | B48: 45860 | C48: Elbow(2) & Socket(2) Payment to Jindal Interiors by Gaurav Ji | D48: Construction | E48: 45860 | F48: 560
A49: 45 | B49: 45860 | C49: Tray(1), Container (3), Platic Tubs(2) to Nanda Ji | F49: 3400
A50: 46 | B50: 45861 | C50: Wiper (2) Payment to Nanda Ji | F50: 500
A51: 47 | B51: 45861 | C51: Flex Printing(2) payment to Nanda ji | F51: 240
A52: 48 | B52: 45860 | C52: Payment to mayank for saman(vijay Sharma) | D52: Event | E52: 45860 | F52: 1000
A53: 49 | B53: 45860 | C53: Sundarkand (10), Chunni (2) payment to Mayank | D53: Event | E53: 45860 | F53: 1740
A54: 50 | B54: 45860 | C54: 2 Folding Bed payment to Mayank | D54: Ops | E54: 45858 | F54: 3600
A55: 51 | B55: 45863 | C55: Stool (12) | D55: Ops | E55: 45863 | F55: 5430
A56: 52 | B56: 45857 | C56: 2 Permanent Marker | D56: Ops | E56: 45857 | F56: 70
A57: 53 | B57: 45857 | C57: Tea Advance | D57: Ops | E57: 45857 | F57: 200
A58: 54 | B58: 45864 | C58: Board & Lock (1 each) | D58: Ops | E58: 45864 | F58: 600
A59: 55 | B59: 45865 | C59: Bathroom Fittings - Store | D59: Construction | E59: 45865 | F59: 375
A60: 56 | B60: 45865 | C60: Electrical material for Store(Extension Board) | D60: Ops | E60: 45865 | F60: 300
A61: 57 | B61: 45865 | C61: Electrical material for Store | D61: Ops | E61: 45865 | F61: 1500
A62: 58 | B62: 45865 | C62: Ansh Phool Wala (26/6/2025 to 31/7/2025) payment done | D62: Ops | E62: No Bill | F62: 2720
A63: 59 | B63: 45865 | C63: Musical Instrument for mandir | F63: 550
A64: 60 | B64: 45865 | C64: Glass Fitting (Flat) + Safai Payment | D64: Ops | E64: 45865 | F64: 800
A65: 61 | B65: 45866 | C65: Dariya (5) | D65: Ops | E65: 45878 | F65: 1500
A66: 62 | B66: 45866 | C66: Recipt Books (6) | D66: Ops | E66: 45866 | F66: 700
A67: 63 | B67: 45867 | C67: Tables (2) | D67: Ops | E67: 45867 | F67: 3200
A68: 64 | B68: 45868 | C68: Payment to Harmeet Contractor | D68: Construction | E68: 45958 | F68: 63650
A69: 65 | B69: 45866 | C69: Bedsheet (3) | D69: Ops | E69: 45866 | F69: 800
A70: 66 | B70: 45871 | C70: Washroom Cleaner + Tea,+ Lassi +Notepad | D70: Ops | E70: 45871 | F70: 330
A71: 67 | B71: 45873 | C71: Garbage Bag | D71: Ops | E71: 45873 | F71: 85
...

Sheet Donation
A1: Sr.No | B1: Date | C1: Donor Name | D1: Phone Number | E1: Flat No. | F1: Mode | G1: Amount | H1: Reference No. | I1: Book/Receipt No | J1: Against Material | K1: Donation Amount With | L1: Amount Given To Treasurer | M1: Collection By | N1: Remarks
A2: 1 | B2: 45802 | C2: Rajesh Nanda Ji | D2: 9315118750 | E2: A1-PH3 | F2: Cash | G2: 11000 | I2: 45658 | K2: Akhilesh | L2: Yes | M2: Rajesh Nanda
A3: 2 | B3: 45802 | C3: Mayank Aggarwal | D3: 9910345533 | E3: B15 GF03 | F3: Cash | G3: 11000 | I3: 45689 | K3: Akhilesh | L3: Yes | M3: Mayank Aggarwal
A4: 3 | B4: 45802 | C4: Akhilesh Mahajan | D4: 9988556660 | E4: B1/404 | F4: Cash | G4: 11000 | I4: 45717 | K4: Akhilesh | L4: Yes | M4: Akhilesh Mahajan
A5: 4 | B5: 45802 | C5: Meenakshi Aggarwal | D5: 9592339372 | E5: C3-GF02 | F5: Cash | G5: 11000 | I5: 45748 | K5: Akhilesh | L5: Yes | M5: Mayank Aggarwal
A6: 5 | B6: 45802 | C6: Gaurav Mahajan | D6: 9888499800 | E6: B9/304 | F6: Cash | G6: 11000 | I6: 45778 | K6: Akhilesh | L6: Yes | M6: Gaurav Mahajan
A7: 6 | B7: 45802 | C7: Amit Vats | D7: 9815387986 | E7: C2/106 | F7: Cash | G7: 11000 | I7: 45809 | K7: Akhilesh | L7: Yes | M7: Amit Vats
A8: 7 | B8: 45802 | C8: Navin Garg | D8: 9814488999 | E8: B9/GF02 | F8: Cash | G8: 11000 | I8: 45839 | K8: Akhilesh | L8: Yes | M8: Akhilesh Mahajan
A9: 8 | B9: 45802 | C9: Padam Jain | D9: 9814815573 | E9: B14/ 403 | F9: Cash | G9: 11000 | I9: 45870 | K9: Akhilesh | L9: Yes | M9: Mayank Aggarwal
A10: 9 | B10: 45802 | C10: Anil Tandon | D10: 9872769299 | F10: Cash | G10: 11000 | I10: 45901 | K10: Akhilesh | L10: Yes | M10: Rajesh Nanda
A11: 10 | B11: 45802 | C11: Aman Sharma | E11: B13/504 | F11: Cash | G11: 11000 | I11: 45931 | K11: Akhilesh | L11: Yes | M11: Mayank Aggarwal
A12: 11 | B12: 45802 | C12: Pranay Srivastava | D12: 9216779477 | E12: B12/501 | F12: Cash | G12: 11000 | I12: 45962 | K12: Akhilesh | L12: Yes | M12: Pranay Srivastava
A13: 12 | B13: 45802 | C13: Saurabh Jain | E13: Noida | F13: Cash | G13: 2100 | I13: 45992 | K13: Akhilesh | L13: Yes | M13: Mayank Aggarwal
A14: 13 | B14: 45808 | C14: Mr.Gandhi | E14: A5 | F14: UPI | G14: 7000 | H14: 515104643031 | I14: 1/13 | J14: 1000 Bricks | K14: Amit Vats | L14: Yes | M14: Walk-In
A15: 14 | B15: 45808 | C15: Sh. Satish Kumar Nanda | E15: Ambala | F15: UPI | G15: 14000 | I15: 1/14 | J15: 2000 Bricks | K15: Nanda Ji | L15: Yes | M15: Rajesh Nanda | N15: Nanda Ji's Father
A16: 15 | B16: 45809 | C16: Kapil Sharma | E16: B12/204 | F16: UPI | G16: 11000 | I16: 1/15 | K16: Nanda Ji | L16: Yes | M16: Rajesh Nanda
A17: 16 | B17: 45809 | C17: Gupt Daan | F17: Cash | G17: 1100 | I17: 1/16 | K17: Akhilesh | L17: Yes | M17: Walk-In
A18: 17 | B18: 45810 | C18: Renu Sharma | E18: Silve City | F18: Cash | G18: 5000 | I18: 1/17 | K18: Akhilesh | L18: Yes | M18: Bajaj Aunty
A19: 18 | B19: 45810 | C19: Ankur Gupta | E19: Chennai | F19: Cash | G19: 5100 | I19: 1/18 | K19: Akhilesh | L19: Yes | M19: Akhilesh Mahajan | N19: Akhilesh's Jija Ji
A20: 19 | B20: 45810 | C20: Gupt Daan | F20: Cash | G20: 1100 | I20: 1/19 | K20: Pranay | L20: Yes | M20: Pranay Srivastava
A21: 20 | B21: 45810 | C21: Mr.S.K Sharma | E21: B12/402 | F21: Cash | G21: 5100 | I21: 1/20 | K21: Pranay | L21: Yes | M21: Pranay Srivastava
A22: 21 | B22: 45810 | C22: Neelu Soi | E22: C3/410 | F22: Cash | G22: 11000 | I22: 1/21 | K22: Akhilesh | L22: Yes | M22: Akhilesh Mahajan
A23: 22 | B23: 45810 | C23: Gupt Daan | F23: Cash | G23: 1000 | I23: 1/22 | K23: Akhilesh | L23: Yes | M23: Bajaj Aunty
A24: 23 | B24: 45810 | C24: Komal | E24: Silver City | F24: UPI | G24: 5200 | I24: 1/23 | K24: Nanda Ji | L24: Yes | M24: Walk-In
A25: 24 | B25: 45810 | C25: Attar Grewal(Rupi) | E25: D3 GF4 | F25: UPI | G25: 500 | I25: 1/24 | K25: Nanda Ji | L25: Yes | M25: Walk-In
A26: 25 | B26: 45810 | C26: Raju Chowdhury | F26: Cash | G26: 11001 | I26: 1/25 | K26: Nanda Ji | L26: Yes | M26: Rajesh Nanda
A27: 26 | B27: 45811 | C27: Gupt Daan | F27: Cash | G27: 5100 | I27: 1/26 | K27: Nanda Ji | L27: Yes | M27: Walk-In
A28: 27 | B28: 45812 | C28: Gurmeet Ji | E28: C4/402 | F28: Cash | G28: 5100 | I28: 1/27 | K28: Amit Vats | L28: Yes | M28: Amit Vats
A29: 28 | B29: 45812 | C29: Sh. Sudarshan Kumar | E29: B12/401 | F29: Cash | G29: 2100 | I29: 1/28 | K29: Pranay | L29: Yes | M29: Pranay Srivastava
A30: 29 | B30: 45812 | C30: Avinash Jaithely | E30: B12/604 | F30: Cash | G30: 501 | I30: 1/29 | K30: Pranay | L30: Yes | M30: Pranay Srivastava
A31: 30 | B31: 45812 | C31: Preeti Katiyar | E31: B-7/301 | F31: Cash | G31: 5100 | I31: 1/30 | K31: Akhilesh | L31: Yes | M31: Akhilesh Mahajan
A32: 31 | B32: 45812 | C32: Surinder Mahajan | E32: Amritsar | F32: Cash | G32: 5100 | I32: 1/31 | K32: Gaurav Mahajan | L32: Yes | M32: Gaurav Mahajan | N32: Gaurav Mahajan's Parents
A33: 32 | B33: 45812 | C33: Ashwani Mahajan | E33: Amritsar | F33: Cash | G33: 2100 | I33: 1/32 | K33: Gaurav Mahajan | L33: Yes | M33: Gaurav Mahajan | N33: Gaurav Mahajan's Brother in law
A34: 33 | B34: 45812 | C34: Dolly Marwaha | E34: Amritsar | F34: Cash | G34: 1100 | I34: 1/33 | K34: Gaurav Mahajan | L34: Yes | M34: Gaurav Mahajan | N34: Gaurav Mahajan's Sister in law
A35: 34 | B35: 45812 | C35: Abhishek | E35: C3-GF11 | F35: Cash | G35: 5100 | I35: 1/34 | K35: Team Meenaksi/Suchi | L35: Yes | M35: Team Meenakshi/Suchi
A36: 35 | B36: 45812 | C36: Khushi | E36: C4-503 | F36: Cash | G36: 2100 | I36: 1/35 | K36: Team Meenaksi/Suchi | L36: Yes | M36: Team Meenakshi/Suchi
A37: 36 | B37: 45812 | C37: Aarav Sethi | E37: C4/501 | F37: Cash | G37: 2100 | I37: 1/36 | K37: Team Meenaksi/Suchi | L37: Yes | M37: Team Meenakshi/Suchi
A38: 37 | B38: 45812 | C38: Trivik | E38: C4-601 | F38: Cash | G38: 2100 | I38: 1/37 | K38: Team Meenaksi/Suchi | L38: Yes | M38: Team Meenakshi/Suchi
A39: 38 | B39: 45812 | C39: Dr.Vishal | E39: C3-311 | F39: Cash | G39: 1100 | I39: 1/38 | K39: Team Meenaksi/Suchi | L39: Yes | M39: Team Meenakshi/Suchi
A40: 39 | B40: 45812 | C40: Sunaina | E40: C3-101 | F40: Cash | G40: 1100 | I40: 1/39 | K40: Team Meenaksi/Suchi | L40: Yes | M40: Team Meenakshi/Suchi
...

Sheet Monthly Sheet
F1: Feburary 2026 | K1: 46082 | P1: 46113 | U1: 46143 | Z1: 46174 | AE1: 46204
A2: Sr.No | B2: Donar Name | C2: Collection By | D2: Phone | E2: Address | F2: Amount | G2: Status | H2: Payment Date | I2: Recipt No | J2: Mode | K2: Amount | L2: Status | M2: Payment Date | N2: Recipt No | O2: Mode | P2: Amount | Q2: Status | R2: Payment Date | S2: Recipt No | T2: Mode | U2: Amount | V2: Status | W2: Payment Date | X2: Recipt No | Y2: Mode | Z2: Amount | AA2: Status | AB2: Payment Date | AC2: Recipt No | AD2: Mode | AE2: Amount | AF2: Status | AG2: Payment Date | AH2: Receipt No | AI2: Mode
F3: =SUM(F4:F200) -> 12500 | K3: =sum(K4:K46) -> 8500 | P3: =sum(P4:P49) -> 8500 | U3: =sum(U4:U55) -> 3000 | Z3: =sum(Z4:Z1000) -> 4500 | AE3: =sum(AE4:AE1000) -> 2000
A4: 1 | B4: Akhilesh Mahajan | C4: Committee | D4: 9988556660 | E4: B1/404 | F4: 500 | G4: Paid | H4: 46071 | I4: SDM/1001 | J4: Cash | K4: 500 | L4: Paid | M4: 46089 | N4: SDM/1026
A5: 2 | B5: Mayank Aggarwal | C5: Committee | D5: 9910345533 | E5: B15/GF03 | F5: 500 | G5: Paid | H5: 46071 | I5: SDM/1002 | J5: Cash
A6: 3 | B6: Aanchal | C6: Team Rajni/Sakshi | D6: 9872790372 | E6: B15/301 | F6: 500 | G6: Paid | H6: 46072 | I6: SDM/1003 | J6: Cash | K6: 500 | L6: Paid | M6: 46096 | N6: SDM/1033 | P6: 500 | Q6: Paid | R6: 46132 | S6: SDM/1044 | T6: Cash
A7: 4 | B7: Neeti Sharma | C7: Team Rajni/Sakshi | D7: 9780333388 | E7: B12/204 | F7: 500 | G7: Paid | H7: 46072 | I7: SDM/1004 | J7: Cash | K7: 500 | L7: Paid | M7: 46096 | N7: SDM/1031 | O7: Cash | P7: 500 | Q7: Paid | R7: 46132 | S7: SDM/1042 | T7: Cash
A8: 5 | B8: Ruchi Gupta | C8: Team Rajni/Sakshi | D8: 9914903824 | E8: B14/101 | F8: 500 | G8: Paid | H8: 46072 | I8: SDM/1005 | J8: Cash | K8: 500 | L8: Paid | M8: 46096 | N8: SDM/1032 | O8: Cash | P8: 500 | Q8: Paid | R8: 46132 | S8: SDM/1043 | T8: Cash
A9: 6 | B9: Vipin Puri | C9: Team Rajni/Sakshi | D9: 9779397624 | E9: B9/102 | F9: 500 | G9: Paid | H9: 46072 | I9: SDM/1006 | J9: Cash | K9: 500 | L9: Paid | M9: 46096 | N9: SDM/1039 | O9: Cash | P9: 500 | Q9: Paid | R9: 46132 | S9: SDM/1051 | T9: Cash
A10: 7 | B10: Rajesh Nanda | C10: Committee | E10: A1/PH03 | F10: 500 | G10: Paid | H10: 46072 | I10: SDM/1007 | J10: Cash
A11: 8 | B11: Amit Vats | C11: Committee | E11: C2/106 | F11: 500 | G11: Paid | H11: 46072 | I11: SDM/1008 | J11: Cash
A12: 9 | B12: Navin Garg | C12: Committee | E12: B9/GF02 | F12: 500 | G12: Paid | H12: 46072 | I12: SDM/1009 | J12: Cash | K12: 500 | L12: Paid | M12: 46096 | N12: SDM/1041 | O12: Cash | P12: 500 | Q12: Paid | R12: 46132 | S12: SDM/1053 | T12: Cash
A13: 10 | B13: Gaurav Mahajan | C13: Committee | E13: B9/604 | F13: 500 | G13: Paid | H13: 46072 | I13: SDM/1010 | J13: Cash
A14: 11 | B14: Pranay Srivastava | C14: Committee | E14: B12/501 | F14: 500 | G14: Paid | H14: 46072 | I14: SDM/1011 | J14: Cash
A15: 12 | B15: Amit Katiyar | C15: Committee | E15: B7/301 | F15: 500 | G15: Paid | H15: 46072 | I15: SDM/1012 | J15: Cash | K15: 500 | L15: Paid | M15: 46089 | N15: SDM/1028 | O15: Cash
A16: 13 | B16: Khullar Aunty | C16: Team Rajni/Sakshi | D16: 7837179012 | E16: B8/302 | F16: 500 | G16: Paid | H16: 46074 | I16: SDM/1013 | J16: Cash | K16: 500 | L16: Paid | M16: 46096 | N16: SDM/1034 | O16: Cash | P16: 500 | Q16: Paid | R16: 46132 | S16: SDM/1046 | T16: Cash | U16: 500 | V16: Paid | W16: 46207 | X16: SDM/1077 | Y16: Cash
A17: 14 | B17: Aditya Nautiyal | C17: Gaurav Mahajan | D17: 9817685000 | E17: D2/603 | F17: 500 | G17: Paid | H17: 46075 | I17: SDM/1014 | J17: Cash
A18: 15 | B18: Hareet Goyal | C18: Gaurav Mahajan | E18: B3/GF01 | F18: 500 | G18: Paid | H18: 46075 | I18: SDM/1015 | J18: Cash
A19: 16 | B19: Dinesh Saklani | C19: Gaurav Mahajan | F19: 500 | G19: Paid | H19: 46075 | I19: SDM/1016 | J19: Cash
A20: 17 | B20: Ish Madaan | C20: Gaurav Mahajan | D20: 9916833888 | E20: B4/402 | F20: 500 | G20: Paid | H20: 46075 | I20: SDM/1017 | J20: Cash
A21: 18 | B21: Sharma Ji | C21: Gaurav Mahajan | D21: 8558986533 | E21: B13/GF03 | F21: 500 | G21: Paid | H21: 46075 | I21: SDM/1018 | J21: Cash
A22: 19 | B22: Manju | C22: Team Rajni/Sakshi | D22: 9988892225 | E22: B8/103 | F22: 500 | G22: Paid | H22: 46076 | I22: SDM/1019 | J22: Cash
A23: 20 | B23: Shikha Mittal | C23: Team Rajni/Sakshi | D23: 8427924051 | E23: B9/303 | F23: 500 | G23: Paid | H23: 46076 | I23: SDM/1020 | J23: Cash | K23: 500 | L23: Paid | M23: 46096 | N23: SDM/1036 | P23: 500 | Q23: Paid | R23: 46132 | S23: SDM/1048 | T23: Cash
A24: 21 | B24: Rohit Nagpal | C24: Akhilesh Mahajan | D24: 9876777108 | E24: B7/202 | F24: 500 | G24: Paid | H24: 46076 | I24: SDM/1021 | J24: Cash
A25: 22 | B25: Ravi Kant | C25: Akhilesh Mahajan | D25: 8837859411 | E25: C2/212 | F25: 500 | G25: Paid | H25: 46078 | I25: SDM/1022 | J25: Cash
A26: 23 | B26: Dina Nath Rajolia | C26: Akhilesh Mahajan | E26: patiala | F26: 500 | G26: Paid | H26: 46079 | I26: SDM/1023 | J26: Cash
A27: 24 | B27: Rana Ji | C27: Gaurav Mahajan | D27: 9991703366 | F27: 500 | G27: Paid | H27: 46079 | I27: SDM/1024 | J27: Cash | K27: 500 | L27: Paid | M27: 46083 | N27: SDM/1026 | O27: Cash | Z27: 500 | AA27: Paid | AB27: 46175 | AC27: SDM/1060 | AD27: Cash | AE27: 500 | AF27: Paid | AG27: 46231 | AI27: Cash
A28: 25 | B28: Lalit Ji | C28: Akhilesh Mahajan | E28: C3/404 | K28: 500 | L28: Paid | M28: 46083 | N28: SDM/1025 | O28: Cash
A29: 26 | B29: Kamal Hasija | C29: Akhilesh Mahajan | K29: 500 | L29: Paid | M29: 46096 | N29: SDM/1030 | O29: Cash | P29: 500 | Q29: Paid | R29: 46175 | S29: SDM/1061 | T29: Cash | U29: 500 | V29: Paid | W29: 46175 | X29: SDM/1062 | Y29: Cash | Z29: 500 | AA29: Paid | AB29: 46175 | AC29: SDM/1063 | AD29: Cash
A30: 27 | B30: Ruchi Aggarwal | C30: Team Rajni/Sakshi | E30: Silver City | K30: 500 | L30: Paid | M30: 46096 | N30: SDM/1035 | O30: Cash | P30: 500 | Q30: Paid | R30: 46132 | S30: SDM/1047 | T30: Cash
A31: 28 | B31: Nirmal Bansal | C31: Team Rajni/Sakshi | E31: B4/202 | K31: 500 | L31: Paid | M31: 46096 | N31: SDM/1037 | O31: Cash | P31: 500 | Q31: Paid | R31: 46132 | S31: SDM/1049 | T31: Cash | Z31: 500 | AA31: Paid | AB31: 46183 | AC31: SDM/1065 | AD31: Cash | AE31: 500 | AF31: Paid | AG31: 46207 | AH31: SDM/1076 | AI31: Cash
A32: 29 | B32: Tripta Garg | C32: Team Rajni/Sakshi | E32: B4/GF02 | K32: 500 | L32: Paid | M32: 46096 | N32: SDM/1038 | O32: Cash | P32: 500 | Q32: Paid | R32: 46132 | S32: SDM/1050 | T32: Cash
A33: 30 | B33: Gaurav Kumar | C33: Team Rajni/Sakshi | E33: B11/GF04 | K33: 500 | L33: Paid | M33: 46096 | N33: SDM/1040 | O33: Cash | P33: 500 | Q33: Paid | R33: 46132 | S33: SDM/1052 | T33: Cash
A34: 31 | B34: Rakesh Karkara | C34: Team Rajni/Sakshi | E34: B12/103 | P34: 500 | Q34: Paid | R34: 46132 | S34: SDM/1045 | T34: Cash
A35: 32 | B35: Prashant Chugh | C35: Akhilesh Mahajan | E35: B11/303
A36: 33 | B36: Padam Jain | C36: Rajesh Nanda | E36: B14 | F36: 500 | G36: Paid | H36: 46175 | I36: SDM/1054 | J36: Cash | K36: 500 | L36: Paid | M36: 46175 | N36: SDM/1055 | O36: Cash | P36: 500 | Q36: Paid | R36: 46175 | S36: SDM/1056 | T36: Cash | U36: 500 | V36: Paid | W36: 46175 | X36: SDM/1057 | Y36: Cash | Z36: 500 | AA36: Paid | AB36: 46175 | AC36: SDM/1058 | AD36: Cash | AE36: 500 | AF36: Paid | AG36: 46175 | AH36: SDM/1059 | AI36: Cash
A37: 34 | B37: Rani Taneja | C37: Team Rajni/Sakshi | Z37: 500 | AA37: Paid | AB37: 46183 | AC37: SDM/1064 | AD37: Cash
A38: 35 | B38: Himani Sharma | C38: Team Meenakshi/Suchi | P38: 500 | Q38: Paid | R38: 46183 | S38: SDM/1066 | T38: Cash | U38: 500 | V38: Paid | W38: 46183 | X38: SDM/1067 | Y38: Cash | Z38: 500 | AA38: Paid | AB38: 46183 | AC38: SDM/1068 | AD38: Cash
A39: 36 | B39: Sagar Kataria | C39: Team Meenakshi/Suchi | P39: 500 | Q39: Paid | R39: 46183 | S39: SDM/1069 | T39: Cash | U39: 500 | V39: Paid | W39: 46183 | X39: SDM/1070 | Y39: Cash | Z39: 500 | AA39: Paid | AB39: 46183 | AC39: SDM/1071 | AD39: Cash
A40: 37 | B40: PArul Munjal | C40: Team Meenakshi/Suchi | P40: 500 | Q40: Paid | R40: 46183 | S40: SDM/1072 | T40: Cash | U40: 500 | V40: Paid | W40: 46183 | X40: SDM/1073 | Y40: Cash | Z40: 500 | AA40: Paid | AB40: 46183 | AC40: SDM/1074 | AD40: Cash
...

Sheet Murti Collection
A1: Date | B1: Donor Name | C1: Phone Number | D1: Flat No. | E1: Mode | F1: Amount | G1: Reference No. | H1: Book/Receipt No | I1: Against Material | J1: Donation Amount With | K1: Amount Given To Treasurer | L1: Collection By | M1: Remarks | O1: Head | P1: Amount | Q1: Date
F2: =SUM(F3:F21) -> 620801 | P2: =SUM(P3:P13) -> 601300 | T2: Murti's Cost | U2: 660101
A3: 45919 | B3: Mr.Ravi Prabhakar | C3: 9872669185 | D3: B11/603 | E3: Cash | F3: 101000 | H3: SDM/7 | J3: Akhilesh | K3: Yes | L3: Mayank Aggarwal | O3: Advance | P3: 125000 | Q3: 45922 | T3: Collection | U3: =F2 -> 620801
A4: 45920 | B4: Mr Padam Jain | C4: 9814815573 | D4: B14 | E4: Cash | F4: 51000 | H4: SDM/8 | J4: Akhilesh | K4: Yes | L4: Mayank Aggarwal | O4: 1st Installment | P4: 196000 | Q4: 45939 | T4: Amount Paid | U4: =P2 -> 601300
A5: 45920 | B5: Gupt Daan | E5: Cash | F5: 61000 | H5: SDM/10 | J5: Akhilesh | K5: Yes | L5: Mayank Aggarwal | O5: 2nd Installment | P5: 98000 | Q5: 45971 | T5: In Hand | U5: =U3-U4 -> 19501
A6: 45921 | B6: Anil Tandon ji | C6: 9872769299 | E6: Cash | F6: 11000 | H6: SDM/517 | J6: Akhilesh | K6: Yes | L6: Mayank Aggarwal | O6: Final Payment | P6: 182300 | Q6: 45978 | T6: Short Money | U6: =U2-U3 -> 39300
A7: 45921 | B7: Soi Family | D7: C Block | E7: Cash | F7: 5100 | H7: SDM/518 | J7: Akhilesh | K7: Yes | L7: Mayank Aggarwal
A8: 45921 | B8: Lucky (Krishan Bhayana) | D8: B1/404 | E8: Cash | F8: 501 | H8: SDM/519 | J8: Akhilesh | K8: Yes | L8: Mayank Aggarwal
A9: 45922 | B9: Suresh Goyal | E9: Cash | F9: 5100 | H9: SDM/520 | J9: Akhilesh | K9: Yes | L9: Mayank Aggarwal
A10: 45922 | B10: Aayansh Mahajan | C10: 9988556660 | D10: B1/404 | E10: Cash | F10: 3100 | H10: SDM/521 | J10: Akhilesh | K10: Yes | L10: Mayank Aggarwal
A11: 45920 | B11: Mr. Abhiney Sharma | D11: B15/GF03 | E11: Cash | F11: 121000 | H11: SDM/11 | J11: Akhilesh | K11: Yes | L11: Mayank Aggarwal
A12: 45950 | B12: Mr. Nanda | E12: Cash | F12: 200000 | H12: SDM/538 | J12: Akhilesh | K12: Yes | L12: Rajesh Nanda
A13: 45970 | B13: Gupt Daan | E13: Cash | F13: 21000 | H13: SDM/541 | J13: Akhilesh | K13: Yes | L13: Akhilesh Mahajan
B14: Amit Vats | E14: Cash | F14: 21000 | H14: SDM/546 | J14: Akhilesh | K14: Yes | L14: Akhilesh Mahajan
B15: Meenakshi Bhabhi | D15: C3 Gf03 | E15: Cash | F15: 20000 | H15: SDM/19 | J15: Akhilesh | K15: Yes | L15: Akhilesh Mahajan

Sheet janamashtami Expenses
A1: Sr.No | B1: Expense | C1: Amount | D1: Expense By
A3: 1 | B3: Ballon Decoration | C3: 2200 | D3: Mayank
A4: 2 | B4: Flower Decoration | C4: 4000 | D4: Comitee
A5: 3 | B5: Fruits | C5: 1350 | D5: Mayank
A6: 4 | B6: Disposals (Dhona, Plates, etc) | C6: 1050 | D6: Mayank
A7: 5 | B7: Prasad Boxes | C7: 840 | D7: Comitee
A8: 6 | B8: Mandir MCB | C8: 220 | D8: Mayank
A9: 7 | B9: 56 Bhog | C9: 1850 | D9: Akhilesh
A10: 8 | B10: 10 Water Crates | C10: 1000 | D10: Pranay
A11: 9 | B11: 10 Water Crates | C11: 1000 | D11: Akhilesh
A12: 10 | B12: Dhol | C12: 1200 | D12: Comitee
A13: 12 | B13: Lights(6) | C13: 4000 | D13: Comitee
A14: 13 | B14: Colors | C14: 260 | D14: Akhilesh
... A19: 18 | B19: Mathura Peda | C19: 1500 | D19: Amit Vats
C21: =SUM(C3:C19) -> 21745
